Workbook

Sheet Parameters
B1: PARAMETERS OF THE NORMAL DISTRIBUTION
B2: Probability | E2: Average Age | G2: Std Dev
B3: =RAND() -> 0.3313535 | E3: =AVERAGE(Data!A1:A251) -> 55.824 | G3: =_xlfn.STDEV.P(Data!A1:A251) -> 17.792612
D5: Popolazione di "Luggnagg"

Sheet Data
A1: Generated age | B1: Group
A2: =MAX(0, ROUND(_xlfn.NORM.INV(RAND(), 57, 18.5), 0)) -> 57 | B2: 2 | H2: Values age | N2: Color legend
A3: =MAX(0, ROUND(_xlfn.NORM.INV(RAND(), 57, 18.5), 0)) -> 71 | B3: 3 | H3: Min | I3: =MIN(A2:A251) -> 14 | N3: Group 1 | O3: 1
A4: =MAX(0, ROUND(_xlfn.NORM.INV(RAND(), 57, 18.5), 0)) -> 82 | B4: 1 | H4: Max | I4: =MAX(A2:A251) -> 123 | N4: Group 2 | O4: 2
A5: =MAX(0, ROUND(_xlfn.NORM.INV(RAND(), 57, 18.5), 0)) -> 73 | B5: 3 | N5: Group 3 | O5: 3
A6: =MAX(0, ROUND(_xlfn.NORM.INV(RAND(), 57, 18.5), 0)) -> 52 | B6: 2 | N6: Group 4 | O6: 4
A7: =MAX(0, ROUND(_xlfn.NORM.INV(RAND(), 57, 18.5), 0)) -> 41 | B7: 2 | F7: Sono state generate due colonne di dati: la prima riporta l’età di 250 individui, la seconda indica il gruppo di appartenenza (da 1 a 4),assegnato in modo casuale e indipendente da qualsiasi parametro. Le età seguono una distribuzione casuale.
A8: =MAX(0, ROUND(_xlfn.NORM.INV(RAND(), 57, 18.5), 0)) -> 58 | B8: 2
A9: =MAX(0, ROUND(_xlfn.NORM.INV(RAND(), 57, 18.5), 0)) -> 43 | B9: 4
A10: =MAX(0, ROUND(_xlfn.NORM.INV(RAND(), 57, 18.5), 0)) -> 65 | B10: 1
A11: =MAX(0, ROUND(_xlfn.NORM.INV(RAND(), 57, 18.5), 0)) -> 57 | B11: 3
A12: =MAX(0, ROUND(_xlfn.NORM.INV(RAND(), 57, 18.5), 0)) -> 67 | B12: 1
A13: =MAX(0, ROUND(_xlfn.NORM.INV(RAND(), 57, 18.5), 0)) -> 57 | B13: 4
A14: =MAX(0, ROUND(_xlfn.NORM.INV(RAND(), 57, 18.5), 0)) -> 33 | B14: 4
A15: =MAX(0, ROUND(_xlfn.NORM.INV(RAND(), 57, 18.5), 0)) -> 49 | B15: 1
A16: =MAX(0, ROUND(_xlfn.NORM.INV(RAND(), 57, 18.5), 0)) -> 60 | B16: 4
A17: =MAX(0, ROUND(_xlfn.NORM.INV(RAND(), 57, 18.5), 0)) -> 55 | B17: 4
A18: =MAX(0, ROUND(_xlfn.NORM.INV(RAND(), 57, 18.5), 0)) -> 57 | B18: 2
A19: =MAX(0, ROUND(_xlfn.NORM.INV(RAND(), 57, 18.5), 0)) -> 74 | B19: 1
... A251: =MAX(0, ROUND(_xlfn.NORM.INV(RAND(), 57, 18.5), 0)) -> 63 | B251: 4

Sheet Sample
A1: Generated age | B1: Group | C1: Chosen sub-sample 2°Group | G1: Group | H1: 2 | K1: Statistical analysis
A2: 5 | B2: 2 | C2: =IF(B2=2,A2,"""Non Gruppo2""") -> 5
A3: 13 | B3: 3 | C3: =IF(B3=2,A3,"""Non Gruppo2""") -> "Non Gruppo2" | G3: Age | H3: Count | J3: È stata creata una colonna che riporta l’età degli individui appartenenti al gruppo 2(56 individui); per tutti gli altri casi, viene indicata la dicitura 'Non gruppo 2'. A fianco è stata realizzata una tabella pivot che consente di ottenere lo stesso risultato mediante una procedura alternativa.Nel medesimo sotto-campione è presente un età minima di 5 anni e un età massima di 103 anni.
A4: 14 | B4: 1 | C4: =IF(B4=2,A4,"""Non Gruppo2""") -> "Non Gruppo2" | G4: 5 | H4: 1
A5: 16 | B5: 3 | C5: =IF(B5=2,A5,"""Non Gruppo2""") -> "Non Gruppo2" | G5: 19 | H5: 1
A6: 19 | B6: 2 | C6: =IF(B6=2,A6,"""Non Gruppo2""") -> 19 | G6: 20 | H6: 2
A7: 20 | B7: 2 | C7: =IF(B7=2,A7,"""Non Gruppo2""") -> 20 | G7: 29 | H7: 1
A8: 20 | B8: 2 | C8: =IF(B8=2,A8,"""Non Gruppo2""") -> 20 | G8: 30 | H8: 2
A9: 20 | B9: 4 | C9: =IF(B9=2,A9,"""Non Gruppo2""") -> "Non Gruppo2" | G9: 32 | H9: 1
A10: 23 | B10: 1 | C10: =IF(B10=2,A10,"""Non Gruppo2""") -> "Non Gruppo2" | G10: 35 | H10: 1
A11: 23 | B11: 3 | C11: =IF(B11=2,A11,"""Non Gruppo2""") -> "Non Gruppo2" | G11: 37 | H11: 1
A12: 25 | B12: 1 | C12: =IF(B12=2,A12,"""Non Gruppo2""") -> "Non Gruppo2" | G12: 39 | H12: 2
A13: 26 | B13: 4 | C13: =IF(B13=2,A13,"""Non Gruppo2""") -> "Non Gruppo2" | G13: 41 | H13: 1
A14: 26 | B14: 4 | C14: =IF(B14=2,A14,"""Non Gruppo2""") -> "Non Gruppo2" | G14: 42 | H14: 1
A15: 27 | B15: 1 | C15: =IF(B15=2,A15,"""Non Gruppo2""") -> "Non Gruppo2" | G15: 43 | H15: 1
... A45: 39 | B45: 2 | C45: =IF(B45=2,A45,"""Non Gruppo2""") -> 39 | G45: 103 | H45: 1
A46: 39 | B46: 2 | C46: =IF(B46=2,A46,"""Non Gruppo2""") -> 39 | G46: Total | H46: 56
A47: 39 | B47: 3 | C47: =IF(B47=2,A47,"""Non Gruppo2""") -> "Non Gruppo2"
A48: 40 | B48: 1 | C48: =IF(B48=2,A48,"""Non Gruppo2""") -> "Non Gruppo2"
A49: 40 | B49: 3 | C49: =IF(B49=2,A49,"""Non Gruppo2""") -> "Non Gruppo2"
A50: 40 | B50: 4 | C50: =IF(B50=2,A50,"""Non Gruppo2""") -> "Non Gruppo2"
A51: 41 | B51: 1 | C51: =IF(B51=2,A51,"""Non Gruppo2""") -> "Non Gruppo2"
A52: 41 | B52: 2 | C52: =IF(B52=2,A52,"""Non Gruppo2""") -> 41
A53: 41 | B53: 4 | C53: =IF(B53=2,A53,"""Non Gruppo2""") -> "Non Gruppo2"
A54: 41 | B54: 3 | C54: =IF(B54=2,A54,"""Non Gruppo2""") -> "Non Gruppo2"
A55: 41 | B55: 1 | C55: =IF(B55=2,A55,"""Non Gruppo2""") -> "Non Gruppo2"
A56: 42 | B56: 4 | C56: =IF(B56=2,A56,"""Non Gruppo2""") -> "Non Gruppo2"
A57: 42 | B57: 2 | C57: =IF(B57=2,A57,"""Non Gruppo2""") -> 42
A58: 43 | B58: 1 | C58: =IF(B58=2,A58,"""Non Gruppo2""") -> "Non Gruppo2"
... A251: 110 | B251: 4 | C251: =IF(B251=2,A251,"""Non Gruppo2""") -> "Non Gruppo2"

Sheet Statistical Insight
A1: Chosen sub-sample 2° Group
A2: 5
A3: 19 | J3: Statistical analysis of the data
A4: 20
A5: 20 | D5: Results with data available
A6: 29 | D6: Media Population | E6: =Parameters!E3 -> 55.824 | G6: Media population : E' la media ottenuta con la formula =Media, calcolata sulla base dei dati relativi alla popolazione.
A7: 30 | D7: Std Dev Population | E7: =Parameters!G3 -> 17.792612 | G7: Std Dev Population: E' la deviazione standard della popolazione ,questo valore indica quanto i dati si disperdono attorno alla media.
A8: 30 | D8: Var Population | E8: =_xlfn.VAR.P(Data!A2:A251) -> 316.57702 | G8: Var Population: La varianza, in questo caso e' un valore piuttosto elevato,che indica un'ampia distribuzione dei dati rispetto alla media.
A9: 32 | D9: Media Sample | E9: =AVERAGE(A2:A57) -> 54.071429 | G9: Media Sample: La media risulta pari a 54,07, calcolata sulla base dei dati relativi al campione (56).
A10: 35 | D10: Var Sample | E10: =_xlfn.VAR.S(A2:A57) -> 387.23117 | G10: Std Dev Sample: Qui ci troviamo con un risultato pari a 19,68, come nel caso di quella della popolazione, il valore indica quanto i dati si disperdono attorno alla media.
A11: 37 | D11: Std Dev Sample | E11: =SQRT(E10) -> 19.67819 | G11: Error Standard :L’errore standard calcolato è 2,63, il che significa che la media campionaria può variare di circa ±2,63 unità rispetto alla vera media della popolazione.
A12: 39 | D12: Error standard | E12: =E11/SQRT(E13) -> 2.6296088
A13: 39 | D13: Sample Count | E13: =COUNT(A2:A57) -> 56
A14: 41 | D14: Confidence Rate | E14: 0.95 | G14: L’intervallo di confidenza al 95%, calcolato sulla media campionaria (54,07), è compreso tra 53,33 e 54,82. Ciò significa che, con un livello di confidenza del 95% (α = 0,05), si stima che la vera media della popolazione si trovi all’interno di questo intervallo. Tuttavia, si osserva che la media della popolazione, non rientra in tale intervallo. Il valore del p-value, ottenuto mediante il test Z a due code, e' un valore nettamente superiore alla soglia di significatività prefissata α=0,05. Pertanto, non si procede al rifiuto dell’ipotesi nulla: non emergono evidenze statisticamente significative tali da affermare che la media del campione differisca in modo significativo da quella della popolazione.
A15: 42 | D15: Alpha | E15: 0.05
A16: 43 | D16: Z-Score | E16: 1.96
A17: 44 | D17: Lower Limit | E17: =E9-E16*E12 -> 48.917395
A18: 45 | D18: Upper Limit | E18: =E9+E16*E12 -> 59.225462
A19: 46
A20: 47
A21: 48 | D21: Estimation of p parameter
A22: 48 | D22: Z | E22: =(E9-E6)/E12 -> -0.66647611
A23: 48 | D23: Test Z | E23: =2*MIN(_xlfn.Z.TEST(A2:A57,E6,E7), 1-_xlfn.Z.TEST(A2:A57,E6,E7)) -> 0.46105779
A24: 49
A25: 49
A26: 50
A27: 51
A28: 52
A29: 53
A30: 54
A31: 54
A32: 55
A33: 55
A34: 56
A35: 58
... A57: 103

Sheet (Un)correlated Variables
A1: Chosen sub-sample 2° Group | B1: Number of Cats | C1: Age of Patner | F1: Pearson linear correlation (Age (sub-sample) -Cats) | L1: Pearson linear correlation (Age (sub-sample) -Age of Patner)
A2: 5 | B2: 0 | C2: 0 | F2: =PEARSON(A2:A57,B2:B57) -> -0.013008976 | I2: =PEARSON(A2:A57,C2:C57) -> 0.98870283
A3: 19 | B3: 0 | C3: 17
A4: 20 | B4: 2 | C4: 17
A5: 20 | B5: 1 | C5: 19
A6: 29 | B6: 1 | C6: 30
A7: 30 | B7: 0 | C7: 32
A8: 30 | B8: 0 | C8: 29
A9: 32 | B9: 2 | C9: 32
A10: 35 | B10: 2 | C10: 31
A11: 37 | B11: 2 | C11: 38
A12: 39 | B12: 0 | C12: 41
A13: 39 | B13: 0 | C13: 36
A14: 41 | B14: 2 | C14: 46
... A19: 46 | B19: 1 | C19: 48
A20: 47 | B20: 0 | C20: 46 | G20: Statistical analysis
A21: 48 | B21: 0 | C21: 43
A22: 48 | B22: 2 | C22: 49 | F22: Le colonne "Number of Cats" e "Age of Partner" sono state generate utilizzando la funzione CASUALE(), in modo da creare valori verosimili per una simulazione realistica. Per la variabile "Number of Cats", i valori sono stati generati come numeri interi compresi tra 0 e 2, simulando la possibilità concreta che un individuo possa avere da zero a due gatti. Per la variabile "Age of Partner", i valori sono stati ottenuti aggiungendo o sottraendo da –5 a +5 anni rispetto all’età dell’individuo, sempre con l’obiettivo di simulare una differenza d’età credibile tra partner.
A23: 48 | B23: 2 | C23: 47
A24: 49 | B24: 2 | C24: 53
A25: 49 | B25: 2 | C25: 47
A26: 50 | B26: 1 | C26: 48
A27: 51 | B27: 0 | C27: 52
A28: 52 | B28: 2 | C28: 51 | F28: Successivamente, è stato calcolato il coefficiente di correlazione di Pearson tra le variabili simulate, per valutare la presenza o meno di relazioni lineari. Per il sottocampione relativo all'età dell’individuo e al numero di gatti posseduti, il coefficiente di Pearson è risultato pari a –0,013. Questo valore è molto vicino a zero e leggermente negativo, indicando una quasi totale assenza di correlazione lineare tra le due variabili. Nel relativo grafico a dispersione, i punti appaiono distribuiti in modo disordinato, senza una direzione chiara, con la linea di tendenza piatta e quasi inclinata verso il basso, confermando l’assenza di relazione lineare.
A29: 53 | B29: 2 | C29: 48
A30: 54 | B30: 0 | C30: 58
A31: 54 | B31: 1 | C31: 52
A32: 55 | B32: 0 | C32: 55
A33: 55 | B33: 2 | C33: 50
A34: 56 | B34: 0 | C34: 58
A35: 58 | B35: 0 | C35: 63 | F35: Nel secondo caso, è stata analizzata la correlazione tra l’età del soggetto e quella del rispettivo partner. Il coefficiente di Pearson calcolato è 0,988, un valore molto elevato e vicino a +1. Questo indica una forte correlazione lineare positiva: all’aumentare dell’età del soggetto, cresce in modo proporzionale anche l’età del partner. Il grafico mostra chiaramente questa relazione: i punti si distribuiscono lungo una retta inclinata positivamente, e la linea di tendenza evidenzia una relazione diretta tra le due variabili.
A36: 59 | B36: 1 | C36: 63
A37: 60 | B37: 0 | C37: 64
A38: 60 | B38: 1 | C38: 64
A39: 61 | B39: 2 | C39: 64
A40: 61 | B40: 1 | C40: 61
A41: 62 | B41: 0 | C41: 66
A42: 65 | B42: 1 | C42: 70
A43: 65 | B43: 0 | C43: 66
A44: 66 | B44: 0 | C44: 68
...

Sheet Linear Regression
A1: Chosen sub-sample 2° Group | B1: Rank | D1: Patecipant Age Rank n°160
A2: 5 | B2: 1 | D2: =_xlfn.FORECAST.LINEAR(160,A2:A57,B2:B57) -> 82.393814 | M2: Y = | N2: {=LINEST(A2:A57,B2:B57,TRUE,FALSE)} -> 0.21537936 | O2: 47.933117 | Q2: correlation estimate table
A3: 84 | B3: 2 | Q3: Results | R3: Consideration
A4: 48 | B4: 3 | Q4: 0,00-0,19 | R4: Molto debole
A5: 50 | B5: 4 | M5: R ² = | N5: =RSQ(A2:A57,B2:B57) -> 0.031865408 | O5: 0.031865408 | Q5: 0,20-0,39 | R5: Debole
A6: 70 | B6: 5 | Q6: 0,40-0,59 | R6: Moderata
A7: 59 | B7: 6 | Q7: 0,60-0,79 | R7: Forte
A8: 54 | B8: 7 | Q8: 0,80-1,00 | R8: Molto forte
A9: 39 | B9: 8
A10: 55 | B10: 9
A11: 49 | B11: 10
A12: 44 | B12: 11
A13: 47 | B13: 12
A14: 20 | B14: 13
A15: 41 | B15: 14
A16: 53 | B16: 15
A17: 60 | B17: 16
A18: 30 | B18: 17 | H18: Statistical analysis
A19: 29 | B19: 18
A20: 20 | B20: 19 | D20: È stata stimata l’età del partecipante in posizione 160 utilizzando la funzione PREVISIONE.LINEARE .In questo modello di regressione lineare: la variabile indipendente (X) è rappresentata dalla posizione nel censimento (da 1 a 56), mentre la variabile dipendente (Y) è costituita dall’età dei partecipanti nel sottocampione. La previsione ha restituito un’età di 82 anni per il partecipante ipotetico in posizione 160. È stato inoltre realizzato un grafico a dispersione (scatter plot) per visualizzare l’andamento dei dati e valutarne la distribuzione. Sul grafico è stata applicata una linea di tendenza con l’equazione della retta di regressione e il relativo coefficiente di determinazione , calcolato anche manualmente per verifica. Il valore di R quadro ottenuto è 0,03187, il che indica che solo il 3,19% circa della variabilità dell’età è spiegata dalla variabilità della posizione nel censimento. Interpretazione: un R quadro così basso evidenzia una correlazione molto debole tra le due variabili: la posizione nel censimento incide in minima parte sull’età dei partecipanti.
A21: 80 | B21: 20
A22: 48 | B22: 21
A23: 73 | B23: 22
A24: 65 | B24: 23
A25: 65 | B25: 24
A26: 54 | B26: 25
A27: 86 | B27: 26
A28: 74 | B28: 27
A29: 61 | B29: 28
A30: 46 | B30: 29
A31: 61 | B31: 30
A32: 19 | B32: 31
... A57: 56 | B57: 56
